2023-04-13 14:16:40,758 INFO    StreamThr :74189 [internal.py:wandb_internal():86] W&B internal server running at pid: 74189, started at: 2023-04-13 14:16:40.757999
2023-04-13 14:16:40,760 DEBUG   HandlerThread:74189 [handler.py:handle_request():144] handle_request: status
2023-04-13 14:16:40,767 INFO    WriterThread:74189 [datastore.py:open_for_write():85] open: ./wandb/run-20230413_141640-kimdjuk0/run-kimdjuk0.wandb
2023-04-13 14:16:40,768 DEBUG   SenderThread:74189 [sender.py:send():375] send: header
2023-04-13 14:16:40,802 DEBUG   SenderThread:74189 [sender.py:send():375] send: run
2023-04-13 14:16:40,804 INFO    SenderThread:74189 [sender.py:_maybe_setup_resume():761] checking resume status for emmazchen/uniprot-nn/kimdjuk0
2023-04-13 14:16:44,238 INFO    SenderThread:74189 [retry.py:__call__():172] Retry attempt failed:
Traceback (most recent call last):
  File "/Users/emmachen/mambaforge/envs/aqlab/lib/python3.10/site-packages/urllib3/connection.py", line 174, in _new_conn
    conn = connection.create_connection(
  File "/Users/emmachen/mambaforge/envs/aqlab/lib/python3.10/site-packages/urllib3/util/connection.py", line 72, in create_connection
    for res in socket.getaddrinfo(host, port, family, socket.SOCK_STREAM):
  File "/Users/emmachen/mambaforge/envs/aqlab/lib/python3.10/socket.py", line 955, in getaddrinfo
    for res in _socket.getaddrinfo(host, port, family, type, proto, flags):
socket.gaierror: [Errno 8] nodename nor servname provided, or not known

During handling of the above exception, another exception occurred:

Traceback (most recent call last):
  File "/Users/emmachen/mambaforge/envs/aqlab/lib/python3.10/site-packages/urllib3/connectionpool.py", line 703, in urlopen
    httplib_response = self._make_request(
  File "/Users/emmachen/mambaforge/envs/aqlab/lib/python3.10/site-packages/urllib3/connectionpool.py", line 386, in _make_request
    self._validate_conn(conn)
  File "/Users/emmachen/mambaforge/envs/aqlab/lib/python3.10/site-packages/urllib3/connectionpool.py", line 1042, in _validate_conn
    conn.connect()
  File "/Users/emmachen/mambaforge/envs/aqlab/lib/python3.10/site-packages/urllib3/connection.py", line 363, in connect
    self.sock = conn = self._new_conn()
  File "/Users/emmachen/mambaforge/envs/aqlab/lib/python3.10/site-packages/urllib3/connection.py", line 186, in _new_conn
    raise NewConnectionError(
urllib3.exceptions.NewConnectionError: <urllib3.connection.HTTPSConnection object at 0x11917d270>: Failed to establish a new connection: [Errno 8] nodename nor servname provided, or not known

During handling of the above exception, another exception occurred:

Traceback (most recent call last):
  File "/Users/emmachen/mambaforge/envs/aqlab/lib/python3.10/site-packages/requests/adapters.py", line 489, in send
    resp = conn.urlopen(
  File "/Users/emmachen/mambaforge/envs/aqlab/lib/python3.10/site-packages/urllib3/connectionpool.py", line 787, in urlopen
    retries = retries.increment(
  File "/Users/emmachen/mambaforge/envs/aqlab/lib/python3.10/site-packages/urllib3/util/retry.py", line 592, in increment
    raise MaxRetryError(_pool, url, error or ResponseError(cause))
urllib3.exceptions.MaxRetryError: HTTPSConnectionPool(host='api.wandb.ai', port=443): Max retries exceeded with url: /graphql (Caused by NewConnectionError('<urllib3.connection.HTTPSConnection object at 0x11917d270>: Failed to establish a new connection: [Errno 8] nodename nor servname provided, or not known'))

During handling of the above exception, another exception occurred:

Traceback (most recent call last):
  File "/Users/emmachen/mambaforge/envs/aqlab/lib/python3.10/site-packages/wandb/sdk/lib/retry.py", line 131, in __call__
    result = self._call_fn(*args, **kwargs)
  File "/Users/emmachen/mambaforge/envs/aqlab/lib/python3.10/site-packages/wandb/sdk/internal/internal_api.py", line 285, in execute
    return self.client.execute(*args, **kwargs)  # type: ignore
  File "/Users/emmachen/mambaforge/envs/aqlab/lib/python3.10/site-packages/wandb/vendor/gql-0.2.0/wandb_gql/client.py", line 52, in execute
    result = self._get_result(document, *args, **kwargs)
  File "/Users/emmachen/mambaforge/envs/aqlab/lib/python3.10/site-packages/wandb/vendor/gql-0.2.0/wandb_gql/client.py", line 60, in _get_result
    return self.transport.execute(document, *args, **kwargs)
  File "/Users/emmachen/mambaforge/envs/aqlab/lib/python3.10/site-packages/wandb/sdk/lib/gql_request.py", line 55, in execute
    request = self.session.post(self.url, **post_args)
  File "/Users/emmachen/mambaforge/envs/aqlab/lib/python3.10/site-packages/requests/sessions.py", line 635, in post
    return self.request("POST", url, data=data, json=json, **kwargs)
  File "/Users/emmachen/mambaforge/envs/aqlab/lib/python3.10/site-packages/requests/sessions.py", line 587, in request
    resp = self.send(prep, **send_kwargs)
  File "/Users/emmachen/mambaforge/envs/aqlab/lib/python3.10/site-packages/requests/sessions.py", line 701, in send
    r = adapter.send(request, **kwargs)
  File "/Users/emmachen/mambaforge/envs/aqlab/lib/python3.10/site-packages/requests/adapters.py", line 565, in send
    raise ConnectionError(e, request=request)
requests.exceptions.ConnectionError: HTTPSConnectionPool(host='api.wandb.ai', port=443): Max retries exceeded with url: /graphql (Caused by NewConnectionError('<urllib3.connection.HTTPSConnection object at 0x11917d270>: Failed to establish a new connection: [Errno 8] nodename nor servname provided, or not known'))
2023-04-13 14:16:45,829 DEBUG   HandlerThread:74189 [handler.py:handle_request():144] handle_request: keepalive
2023-04-13 14:16:50,850 DEBUG   HandlerThread:74189 [handler.py:handle_request():144] handle_request: keepalive
2023-04-13 14:16:55,873 DEBUG   HandlerThread:74189 [handler.py:handle_request():144] handle_request: keepalive
2023-04-13 14:17:00,900 DEBUG   HandlerThread:74189 [handler.py:handle_request():144] handle_request: keepalive
2023-04-13 14:17:05,935 DEBUG   HandlerThread:74189 [handler.py:handle_request():144] handle_request: keepalive
2023-04-13 14:19:52,106 DEBUG   HandlerThread:74189 [handler.py:handle_request():144] handle_request: keepalive
2023-04-13 14:19:57,127 DEBUG   HandlerThread:74189 [handler.py:handle_request():144] handle_request: keepalive
2023-04-13 14:20:02,147 DEBUG   HandlerThread:74189 [handler.py:handle_request():144] handle_request: keepalive
2023-04-13 14:20:07,169 DEBUG   HandlerThread:74189 [handler.py:handle_request():144] handle_request: keepalive
2023-04-13 14:20:12,189 DEBUG   HandlerThread:74189 [handler.py:handle_request():144] handle_request: keepalive
2023-04-13 14:20:15,152 DEBUG   HandlerThread:74189 [handler.py:handle_request():144] handle_request: shutdown
2023-04-13 14:20:15,152 INFO    HandlerThread:74189 [handler.py:finish():845] shutting down handler
2023-04-13 14:20:15,179 INFO    WriterThread:74189 [datastore.py:close():298] close: ./wandb/run-20230413_141640-kimdjuk0/run-kimdjuk0.wandb
2023-04-13 14:20:30,934 INFO    SenderThread:74189 [dir_watcher.py:__init__():219] watching files in: ./wandb/run-20230413_141640-kimdjuk0/files
2023-04-13 14:20:30,935 INFO    SenderThread:74189 [sender.py:_start_run_threads():1124] run started: kimdjuk0 with start time 1681409800.760955
2023-04-13 14:20:30,935 INFO    SenderThread:74189 [sender.py:finish():1550] shutting down sender
2023-04-13 14:20:30,935 INFO    SenderThread:74189 [dir_watcher.py:finish():365] shutting down directory watcher
2023-04-13 14:20:31,941 INFO    SenderThread:74189 [dir_watcher.py:finish():395] scan: ./wandb/run-20230413_141640-kimdjuk0/files
2023-04-13 14:20:31,942 INFO    SenderThread:74189 [dir_watcher.py:finish():409] scan save: ./wandb/run-20230413_141640-kimdjuk0/files/config.yaml config.yaml
2023-04-13 14:20:31,943 INFO    SenderThread:74189 [file_pusher.py:finish():168] shutting down file pusher
2023-04-13 14:20:31,943 INFO    SenderThread:74189 [file_pusher.py:join():173] waiting for file pusher
2023-04-13 14:20:32,494 INFO    wandb-upload_0:74189 [upload_job.py:push():137] Uploaded file ./wandb/run-20230413_141640-kimdjuk0/files/config.yaml
